Workbook
Name IQ_CH: 110000
Name IQ_CQ: 5000
Name IQ_CY: 10000
Name IQ_DAILY: 500000
Name IQ_FH: 100000
Name IQ_FQ: 500
Name IQ_FY: 1000
Name IQ_LTM: 2000
Name IQ_MONTH: 15000
Name IQ_NTM: 6000
Name IQ_WEEK: 50000
Name IQ_YTD: 3000

Sheet _CIQHiddenCacheSheet
A1: 15 | B1: AwABTAVMT0NBTAFI/////wFQPgAAACxDSVEuTkFTREFRR1M6TU5TVC5JUV9NQVJLRVRDQVAuMy8xOS8yMDE0LlVTRAEAAACxPgUAAgAAAAsxMTYxNy45NzY3NAEGAAAABQAAAAExAQAAAAoxNjYxMjI3MjI2AwAAAAMxNjACAAAABjEwMDA1NAQAAAABMAcAAAAJMy8xOS8yMDE0TEhDuK8R0QhT00YnshHRCDFDSVEuTkFTREFRR1M6TU5TVC5JUV9OSV9OT1JNLjIwMDAuMy8xOS8yMDE0Li4uVVNEAQAAALE+BQACAAAACjM1Ny40ODY4NzUBCAAAAAUAAAABMQEAAAAKMTY2MTIyNzE2MQMAAAADMTYwAgAAAAQ0Mzc4BAAAAAEwBwAAAAkzLzE5LzIwMTQIAAAACjEyLzMxLzIwMTMJAAAAATBw0vpIsRHRCFPTRieyEdEIHUNJUS5OWVNFOktPLklRX01BUktFVENBUC4uVVNEAQAAABJoAAACAAAADDE2ODA0MC43NTkwMgEGAAAABQAAAAExAQAAAAoxNjYwNzU3ODQzAwAAAAMxNjACAAAABjEwMDA1NAQAAAABMAcAAAAJMy8xOS8yMDE0TEhDuK8R0Qg3fBTtsRHRCDNDSVEuTllTRTpEUFMuSVFfRElMVVRfRVBTX05PUk0uMjAwMC4zLzE5LzIwMTQuLi5VU0QBAAAAxxqNAAIAAAAIMy4wMzE3ODQBCAAAAAUAAAABMQEAAAAKMTY1OTQyMTUwMQMAAAADMTYwAgAAAAQ0MzgwBAAAAAEwBwAAAAkzLzE5LzIwMTQIAAAACjEyLzMxLzIwMTMJAAAAATCD2ZMZsRHRCIC3mhmxEdEIKkNJUS5OWVNFOlBFUC5JUV9ESUxVVF9FUFNfTk9 | C1: STS4yMDAwLi4uLlVTRAEAAABWgAAAAgAAAAgzLjYwMTI4MgEIAAAABQAAAAExAQAAAAoxNjU4MzQyMjU4AwAAAAMxNjACAAAABDQzODAEAAAAATAHAAAACTMvMTkvMjAxNAgAAAAKMTIvMjgvMjAxMwkAAAABMOXbLBexEdEIN300F7ER0QgmQ0lRLk5BU0RBUUdTOk1OU1QuSVFfVEVWLjMvMTkvMjAxNC5VU0QBAAAAsT4FAAIAAAALMTEwMDQuMzgwNzQBBgAAAAUAAAABMQEAAAAKMTY2MTIyNzIyNgMAAAADMTYwAgAAAAYxMDAwNjAEAAAAATAHAAAACTMvMTkvMjAxNBQVWmCwEdEIMYVGJ7IR0QggQ0lRLk5ZU0U6UEVQLklRX0VCSVQuMjAwMC4uLi5VU0QBAAAAVoAAAAIAAAAEOTg3OAEIAAAABQAAAAExAQAAAAoxNjU4MzQyMjU4AwAAAAMxNjACAAAAAzQwMAQAAAABMAcAAAAJMy8xOS8yMDE0CAAAAAoxMi8yOC8yMDEzCQAAAAEw16lM67AR0QiQ61LrsBHRCB5DSVEuT1RDUEs6SlNEQS5JUV9DT01QQU5ZX05BTUUBAAAAaFYGAAMAAAAOSm9uZXMgU29kYSBDby4ADZZ0O68R0QidZhXtsRHRCCxDSVEuTkFTREFRR1M6RklaWi5JUV9NQVJLRVRDQVAuMy8xOS8yMDE0LlVTRAEAAACa6AQAAgAAAAk5NjQuMTg5NzMBBgAAAAUAAAABMQEAAAAKMTY2MTQwMzUyNAMAAAADMTYwAgAAAAYxMDAwNTQEAAAAATAHAAAACTMvMTkvMjAxNExIQ7ivEdEIU9NGJ7IR0QguQ0lRLk5BU0RBUUdTOkZJWlouSVFfRUJJVC4yMDAwLj | D1: MvMTkvMjAxNC4uLlVTRAEAAACa6AQAAgAAAAY2Ni4xMzkBCAAAAAUAAAABMQEAAAAKMTY2MTQwMzg0NQMAAAADMTYwAgAAAAM0MDAEAAAAATAHAAAACTMvMTkvMjAxNAgAAAAJMS8yNS8yMDE0CQAAAAEw+/vx7rAR0QhCrEYnshHRCDNDSVEuTllTRTpQRVAuSVFfRElMVVRfRVBTX05PUk0uMjAwMC4zLzE5LzIwMTQuLi5VU0QBAAAAVoAAAAIAAAAIMy42MDEyODIBCAAAAAUAAAABMQEAAAAKMTY1ODM0MjI1OAMAAAADMTYwAgAAAAQ0MzgwBAAAAAEwBwAAAAkzLzE5LzIwMTQIAAAACjEyLzI4LzIwMTMJAAAAATDl2ywXsRHRCDd9NBexEdEIJ0NJUS5OWVNFOkRQUy5JUV9NQVJLRVRDQVAuMy8xOS8yMDE0LlVTRAEAAADHGo0AAgAAAAsxMDMyNS44ODkzOAEGAAAABQAAAAExAQAAAAoxNjU5NDIxNjE1AwAAAAMxNjACAAAABjEwMDA1NAQAAAABMAcAAAAJMy8xOS8yMDE0TEhDuK8R0QhCrEYnshHRCCxDSVEuTllTRTpQRVAuSVFfTklfTk9STS4yMDAwLjMvMTkvMjAxNC4uLlVTRAEAAABWgAAAAgAAAAQ1NjE4AQgAAAAFAAAAATEBAAAACjE2NTgzNDIyNTgDAAAAAzE2MAIAAAAENDM3OAQAAAABMAcAAAAJMy8xOS8yMDE0CAAAAAoxMi8yOC8yMDEzCQAAAAEwLkDjPrER0QhCrEYnshHRCCNDSVEuT1RDUEs6SlNEQS5JUV9URVYuMy8xOS8yMDE0LlVTRAEAAABoVgYAAgAAAAkxNi4zNzE3OTEBBgAAAAUAAAABMQEAA | E1: AAKMTY2MTY3NTAwNgMAAAADMTYwAgAAAAYxMDAwNjAEAAAAATAHAAAACTMvMTkvMjAxNBQVWmCwEdEISKMU7bER0QgpQ0lRLk5ZU0U6S08uSVFfRElMVVRfRVBTX05PUk0uMjAwMC4uLi5VU0QBAAAAEmgAAAIAAAAIMS42MzY4MzcBCAAAAAUAAAABMQEAAAAKMTY2MDc1NjM1NQMAAAADMTYwAgAAAAQ0MzgwBAAAAAEwBwAAAAkzLzE5LzIwMTQIAAAACjEyLzMxLzIwMTMJAAAAATCD2ZMZsRHRCG+QmhmxEdEIM0NJUS5OQVNEQVFHUzpNTlNULklRX1RPVEFMX1JFVi4yMDAwLjMvMTkvMjAxNC4uLlVTRAEAAACxPgUAAgAAAAgyMjQ2LjQyOAEIAAAABQAAAAExAQAAAAoxNjYxMjI3MTYxAwAAAAMxNjACAAAAAjI4BAAAAAEwBwAAAAkzLzE5LzIwMTQIAAAACjEyLzMxLzIwMTMJAAAAATBcdHmtsBHRCFPTRieyEdEIJkNJUS5OQVNEQVFHUzpGSVpaLklRX1RFVi4zLzE5LzIwMTQuVVNEAQAAAJroBAACAAAACTk2Ny41MjQ3MwEGAAAABQAAAAExAQAAAAoxNjYxNDAzNTI0AwAAAAMxNjACAAAABjEwMDA2MAQAAAABMAcAAAAJMy8xOS8yMDE0FBVaYLAR0QgxhUYnshHRCCxDSVEuTllTRTpEUFMuSVFfTklfTk9STS4yMDAwLjMvMTkvMjAxNC4uLlVTRAEAAADHGo0AAgAAAAM2MjABCAAAAAUAAAABMQEAAAAKMTY1OTQyMTUwMQMAAAADMTYwAgAAAAQ0Mzc4BAAAAAEwBwAAAAkzLzE5LzIwMTQIAAAACjEyLzMxLzIwMTMJ | F1: AAAAATBw0vpIsRHRCEKsRieyEdEII0NJUS5OWVNFOlBFUC5JUV9OSV9OT1JNLjIwMDAuLi4uVVNEAQAAAFaAAAACAAAABDU2MTgBCAAAAAUAAAABMQEAAAAKMTY1ODM0MjI1OAMAAAADMTYwAgAAAAQ0Mzc4BAAAAAEwBwAAAAkzLzE5LzIwMTQIAAAACjEyLzI4LzIwMTMJAAAAATAuQOM+sRHRCE1s6j6xEdEILkNJUS5OWVNFOkRQUy5JUV9UT1RBTF9SRVYuMjAwMC4zLzE5LzIwMTQuLi5VU0QBAAAAxxqNAAIAAAAENTk5NwEIAAAABQAAAAExAQAAAAoxNjU5NDIxNTAxAwAAAAMxNjACAAAAAjI4BAAAAAEwBwAAAAkzLzE5LzIwMTQIAAAACjEyLzMxLzIwMTMJAAAAATBcdHmtsBHRCFPTRieyEdEIK0NJUS5OWVNFOlBFUC5JUV9MQVNUU0FMRVBSSUNFLjMvMTkvMjAxNC5VU0QBAAAAVoAAAAIAAAAFODEuMzcAp8xSi68R0Qhk+kYnshHRCDNDSVEuTkFTREFRR1M6RklaWi5JUV9UT1RBTF9SRVYuMjAwMC4zLzE5LzIwMTQuLi5VU0QBAAAAmugEAAIAAAAGNjQ0LjY2AQgAAAAFAAAAATEBAAAACjE2NjE0MDM4NDUDAAAAAzE2MAIAAAACMjgEAAAAATAHAAAACTMvMTkvMjAxNAgAAAAJMS8yNS8yMDE0CQAAAAEwXHR5rbAR0QhT00YnshHRCCtDSVEuTllTRTpEUFMuSVFfRUJJVERBLjIwMDAuMy8xOS8yMDE0Li4uVVNEAQAAAMcajQACAAAABDEzMTkBCAAAAAUAAAABMQEAAAAKMTY1OTQyMTUwMQMAAAADMTYwAgAAAAQ | G1: 0MDUxBAAAAAEwBwAAAAkzLzE5LzIwMTQIAAAACjEyLzMxLzIwMTMJAAAAATDu+DTdsBHRCDGFRieyEdEIIENJUS5OWVNFOktPLklRX1RFVi4zLzE5LzIwMTQuVVNEAQAAABJoAAACAAAADDE4NTEyMS43NTkwMgEGAAAABQAAAAExAQAAAAoxNjYwNzU3ODQzAwAAAAMxNjACAAAABjEwMDA2MAQAAAABMAcAAAAJMy8xOS8yMDE0FBVaYLAR0QggXkYnshHRCDVDSVEuT1RDUEs6SlNEQS5JUV9ESUxVVF9FUFNfTk9STS4yMDAwLjMvMTkvMjAxNC4uLlVTRAEAAABoVgYAAgAAAAktMC4wMjk2MDMBCAAAAAUAAAABMQEAAAAKMTY2MjUxMTgyNgMAAAADMTYwAgAAAAQ0MzgwBAAAAAEwBwAAAAkzLzE5LzIwMTQIAAAACjEyLzMxLzIwMTMJAAAAATCD2ZMZsRHRCJHemhmxEdEIG0NJUS5OWVNFOktPLklRX0NPTVBBTllfTkFNRQEAAAASaAAAAwAAABVUaGUgQ29jYS1Db2xhIENvbXBhbnkADZZ0O68R0Qhk+kYnshHRCDhDSVEuTkFTREFRR1M6RklaWi5JUV9ESUxVVF9FUFNfTk9STS4yMDAwLjMvMTkvMjAxNC4uLlVTRAEAAACa6AQAAgAAAAgwLjg4MTMxOQEIAAAABQAAAAExAQAAAAoxNjYxNDAzODQ1AwAAAAMxNjACAAAABDQzODAEAAAAATAHAAAACTMvMTkvMjAxNAgAAAAJMS8yNS8yMDE0CQAAAAEwg9mTGbER0QiAt5oZsRHRCCZDSVEuTllTRTpLTy5JUV9NQVJLRVRDQVAuMy8xOS8yMDE0LlVTRAEAAAASaAAAAgAAAA | H1: wxNjgwNDAuNzU5MDIBBgAAAAUAAAABMQEAAAAKMTY2MDc1Nzg0MwMAAAADMTYwAgAAAAYxMDAwNTQEAAAAATAHAAAACTMvMTkvMjAxNExIQ7ivEdEIQqxGJ7IR0QgqQ0lRLk5ZU0U6S08uSVFfTEFTVFNBTEVQUklDRS4zLzE5LzIwMTQuVVNEAQAAABJoAAACAAAABTM4LjE0AENdCJCvEdEIZPpGJ7IR0QgpQ0lRLk5ZU0U6UEVQLklRX0VCSVQuMjAwMC4zLzE5LzIwMTQuLi5VU0QBAAAAVoAAAAIAAAAEOTg3OAEIAAAABQAAAAExAQAAAAoxNjU4MzQyMjU4AwAAAAMxNjACAAAAAzQwMAQAAAABMAcAAAAJMy8xOS8yMDE0CAAAAAoxMi8yOC8yMDEzCQAAAAEw16lM67AR0QgxhUYnshHRCDJDSVEuTllTRTpLTy5JUV9ESUxVVF9FUFNfTk9STS4yMDAwLjMvMTkvMjAxNC4uLlVTRAEAAAASaAAAAgAAAAgxLjYzNjgzNwEIAAAABQAAAAExAQAAAAoxNjYwNzU2MzU1AwAAAAMxNjACAAAABDQzODAEAAAAATAHAAAACTMvMTkvMjAxNAgAAAAKMTIvMzEvMjAxMwkAAAABMIPZkxmxEdEIgLeaGbER0QgtQ0lRLk9UQ1BLOkpTREEuSVFfTEFTVFNBTEVQUklDRS4zLzE5LzIwMTQuVVNEAQAAAGhWBgACAAAABDAuNDYAQ10IkK8R0QiMPxXtsRHRCCtDSVEuTllTRTpEUFMuSVFfTEFTVFNBTEVQUklDRS4zLzE5LzIwMTQuVVNEAQAAAMcajQACAAAABTUyLjMxAENdCJCvEdEIZPpGJ7IR0QgrQ0lRLk5ZU0U6UEVQLklRX0VCSVREQ | I1: S4yMDAwLjMvMTkvMjAxNC4uLlVTRAEAAABWgAAAAgAAAAUxMjM0NAEIAAAABQAAAAExAQAAAAoxNjU4MzQyMjU4AwAAAAMxNjACAAAABDQwNTEEAAAAATAHAAAACTMvMTkvMjAxNAgAAAAKMTIvMjgvMjAxMwkAAAABMBkFBtewEdEIIF5GJ7IR0QgcQ0lRLk5ZU0U6RFBTLklRX0NPTVBBTllfTkFNRQEAAADHGo0AAwAAAB1EciBQZXBwZXIgU25hcHBsZSBHcm91cCwgSW5jLgCV7i1LrxHRCGT6RieyEdEILkNJUS5PVENQSzpKU0RBLklRX05JX05PUk0uMjAwMC4zLzE5LzIwMTQuLi5VU0QBAAAAaFYGAAIAAAAHLTEuMTQyNQEIAAAABQAAAAExAQAAAAoxNjYyNTExODI2AwAAAAMxNjACAAAABDQzNzgEAAAAATAHAAAACTMvMTkvMjAxNAgAAAAKMTIvMzEvMjAxMwkAAAABMHDS+kixEdEISKMU7bER0QgtQ0lRLk5ZU0U6S08uSVFfVE9UQUxfUkVWLjIwMDAuMy8xOS8yMDE0Li4uVVNEAQAAABJoAAACAAAABTQ2ODU0AQgAAAAFAAAAATEBAAAACjE2NjA3NTYzNTUDAAAAAzE2MAIAAAACMjgEAAAAATAHAAAACTMvMTkvMjAxNAgAAAAKMTIvMzEvMjAxMwkAAAABMFx0ea2wEdEIU9NGJ7IR0QgXQ0lRLk5ZU0U6S08uSVFfVEVWLi5VU0QBAAAAEmgAAAIAAAAMMTg1MTIxLjc1OTAyAQYAAAAFAAAAATEBAAAACjE2NjA3NTc4NDMDAAAAAzE2MAIAAAAGMTAwMDYwBAAAAAEwBwAAAAkzLzE5LzIwMTQUFVpgsBHRCCBeRiey | J1: EdEIOENJUS5OQVNEQVFHUzpNTlNULklRX0RJTFVUX0VQU19OT1JNLjIwMDAuMy8xOS8yMDE0Li4uVVNEAQAAALE+BQACAAAACDIuMDYxNzg1AQgAAAAFAAAAATEBAAAACjE2NjEyMjcxNjEDAAAAAzE2MAIAAAAENDM4MAQAAAABMAcAAAAJMy8xOS8yMDE0CAAAAAoxMi8zMS8yMDEzCQAAAAEwg9mTGbER0QiAt5oZsRHRCCtDSVEuTllTRTpLTy5JUV9OSV9OT1JNLjIwMDAuMy8xOS8yMDE0Li4uVVNEAQAAABJoAAACAAAABjczODAuNQEIAAAABQAAAAExAQAAAAoxNjYwNzU2MzU1AwAAAAMxNjACAAAABDQzNzgEAAAAATAHAAAACTMvMTkvMjAxNAgAAAAKMTIvMzEvMjAxMwkAAAABMHDS+kixEdEIQqxGJ7IR0QgfQ0lRLk5ZU0U6S08uSVFfRUJJVC4yMDAwLi4uLlVTRAEAAAASaAAAAgAAAAUxMTEyNwEIAAAABQAAAAExAQAAAAoxNjYwNzU2MzU1AwAAAAMxNjACAAAAAzQwMAQAAAABMAcAAAAJMy8xOS8yMDE0CAAAAAoxMi8zMS8yMDEzCQAAAAEw+/vx7rAR0QiAEvrusBHRCCFDSVEuTllTRTpEUFMuSVFfVEVWLjMvMTkvMjAxNC5VU0QBAAAAxxqNAAIAAAALMTI3NjMuODg5MzgBBgAAAAUAAAABMQEAAAAKMTY1OTQyMTYxNQMAAAADMTYwAgAAAAYxMDAwNjAEAAAAATAHAAAACTMvMTkvMjAxNBQVWmCwEdEIMYVGJ7IR0QgwQ0lRLk5BU0RBUUdTOkZJWlouSVFfTEFTVFNBTEVQUklDRS4zLzE5LzIwMTQuVVNEAQA | K1: AAJroBAACAAAABTIwLjgxAENdCJCvEdEIZPpGJ7IR0QgwQ0lRLk5BU0RBUUdTOkZJWlouSVFfRUJJVERBLjIwMDAuMy8xOS8yMDE0Li4uVVNEAQAAAJroBAACAAAABjc3LjYxNQEIAAAABQAAAAExAQAAAAoxNjYxNDAzODQ1AwAAAAMxNjACAAAABDQwNTEEAAAAATAHAAAACTMvMTkvMjAxNAgAAAAJMS8yNS8yMDE0CQAAAAEw/x813bAR0QgxhUYnshHRCCtDSVEuT1RDUEs6SlNEQS5JUV9FQklULjIwMDAuMy8xOS8yMDE0Li4uVVNEAQAAAGhWBgACAAAABi0xLjgzOAEIAAAABQAAAAExAQAAAAoxNjYyNTExODI2AwAAAAMxNjACAAAAAzQwMAQAAAABMAcAAAAJMy8xOS8yMDE0CAAAAAoxMi8zMS8yMDEzCQAAAAEw+/vx7rAR0QhZyhTtsRHRCCFDSVEuTkFTREFRR1M6RklaWi5JUV9DT01QQU5ZX05BTUUBAAAAmugEAAMAAAAXTmF0aW9uYWwgQmV2ZXJhZ2UgQ29ycC4ADZZ0O68R0Qhk+kYnshHRCCFDSVEuTllTRTpQRVAuSVFfVEVWLjMvMTkvMjAxNC5VU0QBAAAAVoAAAAIAAAAMMTQzODI0LjA1ODQyAQYAAAAFAAAAATEBAAAACjE2NTgzNDM0MDQDAAAAAzE2MAIAAAAGMTAwMDYwBAAAAAEwBwAAAAkzLzE5LzIwMTR8F0ldsBHRCCBeRieyEdEIMUNJUS5OQVNEQVFHUzpGSVpaLklRX05JX05PUk0uMjAwMC4zLzE5LzIwMTQuLi5VU0QBAAAAmugEAAIAAAAJNDAuOTkwNjI1AQgAAAAFAAAAATEBAAAACjE2NjE0MD | L1: M4NDUDAAAAAzE2MAIAAAAENDM3OAQAAAABMAcAAAAJMy8xOS8yMDE0CAAAAAkxLzI1LzIwMTQJAAAAATBw0vpIsRHRCFPTRieyEdEILkNJUS5OQVNEQVFHUzpNTlNULklRX0VCSVQuMjAwMC4zLzE5LzIwMTQuLi5VU0QBAAAAsT4FAAIAAAAHNTgzLjcxNgEIAAAABQAAAAExAQAAAAoxNjYxMjI3MTYxAwAAAAMxNjACAAAAAzQwMAQAAAABMAcAAAAJMy8xOS8yMDE0CAAAAAoxMi8zMS8yMDEzCQAAAAEw+/vx7rAR0QhCrEYnshHRCDBDSVEuT1RDUEs6SlNEQS5JUV9UT1RBTF9SRVYuMjAwMC4zLzE5LzIwMTQuLi5VU0QBAAAAaFYGAAIAAAAGMTMuNjk2AQgAAAAFAAAAATEBAAAACjE2NjI1MTE4MjYDAAAAAzE2MAIAAAACMjgEAAAAATAHAAAACTMvMTkvMjAxNAgAAAAKMTIvMzEvMjAxMwkAAAABMFx0ea2wEdEIexgV7bER0QgoQ0lRLk5ZU0U6S08uSVFfRUJJVC4yMDAwLjMvMTkvMjAxNC4uLlVTRAEAAAASaAAAAgAAAAUxMTEyNwEIAAAABQAAAAExAQAAAAoxNjYwNzU2MzU1AwAAAAMxNjACAAAAAzQwMAQAAAABMAcAAAAJMy8xOS8yMDE0CAAAAAoxMi8zMS8yMDEzCQAAAAEw+/vx7rAR0QgxhUYnshHRCDBDSVEuTkFTREFRR1M6TU5TVC5JUV9MQVNUU0FMRVBSSUNFLjMvMTkvMjAxNC5VU0QBAAAAsT4FAAIAAAAFNjkuNjIAQ10IkK8R0Qhk+kYnshHRCBxDSVEuTllTRTpQRVAuSVFfQ09NUEFOWV9OQU1FAQAAA | M1: FaAAAADAAAADVBlcHNpY28sIEluYy4A6ytnM68R0Qh1IUcnshHRCC5DSVEuTllTRTpQRVAuSVFfVE9UQUxfUkVWLjIwMDAuMy8xOS8yMDE0Li4uVVNEAQAAAFaAAAACAAAABTY2NDE1AQgAAAAFAAAAATEBAAAACjE2NTgzNDIyNTgDAAAAAzE2MAIAAAACMjgEAAAAATAHAAAACTMvMTkvMjAxNAgAAAAKMTIvMjgvMjAxMwkAAAABMN56ZauwEdEIU9NGJ7IR0QgtQ0lRLk9UQ1BLOkpTREEuSVFfRUJJVERBLjIwMDAuMy8xOS8yMDE0Li4uVVNEAQAAAGhWBgACAAAABi0xLjYwNgEIAAAABQAAAAExAQAAAAoxNjYyNTExODI2AwAAAAMxNjACAAAABDQwNTEEAAAAATAHAAAACTMvMTkvMjAxNAgAAAAKMTIvMzEvMjAxMwkAAAABMP8fNd2wEdEIavEU7bER0QgqQ0lRLk5ZU0U6S08uSVFfRUJJVERBLjIwMDAuMy8xOS8yMDE0Li4uVVNEAQAAABJoAAACAAAABTEzMTA0AQgAAAAFAAAAATEBAAAACjE2NjA3NTYzNTUDAAAAAzE2MAIAAAAENDA1MQQAAAABMAcAAAAJMy8xOS8yMDE0CAAAAAoxMi8zMS8yMDEzCQAAAAEw7vg03bAR0QggXkYnshHRCCJDSVEuTllTRTpLTy5JUV9OSV9OT1JNLjIwMDAuLi4uVVNEAQAAABJoAAACAAAABjczODAuNQEIAAAABQAAAAExAQAAAAoxNjYwNzU2MzU1AwAAAAMxNjACAAAABDQzNzgEAAAAATAHAAAACTMvMTkvMjAxNAgAAAAKMTIvMzEvMjAxMwkAAAABMHDS+kixEdEIoCUCSbER0Qgw | N1: Q0lRLk5BU0RBUUdTOk1OU1QuSVFfRUJJVERBLjIwMDAuMy8xOS8yMDE0Li4uVVNEAQAAALE+BQACAAAABzYwNi40NzgBCAAAAAUAAAABMQEAAAAKMTY2MTIyNzE2MQMAAAADMTYwAgAAAAQ0MDUxBAAAAAEwBwAAAAkzLzE5LzIwMTQIAAAACjEyLzMxLzIwMTMJAAAAATD/HzXdsBHRCDGFRieyEdEIKUNJUS5OWVNFOkRQUy5JUV9FQklULjIwMDAuMy8xOS8yMDE0Li4uVVNEAQAAAMcajQACAAAABDExMDMBCAAAAAUAAAABMQEAAAAKMTY1OTQyMTUwMQMAAAADMTYwAgAAAAM0MDAEAAAAATAHAAAACTMvMTkvMjAxNAgAAAAKMTIvMzEvMjAxMwkAAAABMPv78e6wEdEIQqxGJ7IR0QgpQ0lRLk9UQ1BLOkpTREEuSVFfTUFSS0VUQ0FQLjMvMTkvMjAxNC5VU0QBAAAAaFYGAAIAAAAJMTcuODA2NzkxAQYAAAAFAAAAATEBAAAACjE2NjE2NzUwMDYDAAAAAzE2MAIAAAAGMTAwMDU0BAAAAAEwBwAAAAkzLzE5LzIwMTRMSEO4rxHRCEijFO2xEdEIIUNJUS5OQVNEQVFHUzpNTlNULklRX0NPTVBBTllfTkFNRQEAAACxPgUAAwAAABxNb25zdGVyIEJldmVyYWdlIENvcnBvcmF0aW9uAA2WdDuvEdEIZPpGJ7IR0QgnQ0lRLk5ZU0U6UEVQLklRX01BUktFVENBUC4zLzE5LzIwMTQuVVNEAQAAAFaAAAACAAAADDEyMzg4My4wNTg0MgEGAAAABQAAAAExAQAAAAoxNjU4MzQzNDA0AwAAAAMxNjACAAAABjEwMDA1NAQAAAABMAcAAAA | O1: JMy8xOS8yMDE0tJ/1ta8R0QhCrEYnshHRCA==

Sheet Cover Page
C12: Comparable Company Analysis
C19: Table of Contents
C21: Comps Table
C22: Microsoft DCF Model
C23: Microsoft 3-Statement Model
C24: Apple DCF Model
C25: Apple 3-Statement Model
C26: Sensitivity Analysis Table
C27: Valuation Range Chart

Sheet Comps Table
B2: Apple vs. Microsoft Valuation Comparison
B4: Financial data in $ millions, except per-share data and multiples | C4: Market Data | G4: Financial Data | L4: Valuation
C5: Price | D5: Market Cap | E5: EV | G5: Sales | H5: EBITDA | I5: EBIT | J5: Earnings | L5: EV/Sales | M5: EV/EBITDA | N5: EV/EBIT | O5: P/E
B6: Company Name | C6: ($/share) | D6: ($M) | E6: ($M) | G6: ($M) | H6: ($M) | I6: ($M) | J6: ($M) | L6: x | M6: x | N6: x | O6: x
B7: Apple | C7: ='Apple DCF Model'!D12 -> 231.27 | D7: ='Apple DCF Model'!I31 -> 3495877.3 | E7: ='Apple DCF Model'!I34 -> 3516456.3 | G7: ='Apple 3-Statement Model'!H26 -> 391035 | H7: ='Apple 3-Statement Model'!H34+'Apple 3-Statement Model'!H66 -> 134661 | I7: ='Apple 3-Statement Model'!H34 -> 123216 | J7: ='Apple 3-Statement Model'!H37 -> 93736 | L7: =E7/G7 -> 8.9926895 | M7: =E7/H7 -> 26.113398 | N7: =E7/I7 -> 28.538959 | O7: =D7/J7 -> 37.294927
B8: Microsoft | C8: ='Microsoft DCF Model'!D12 -> 384.41 | D8: ='Microsoft DCF Model'!I31 -> 2869620.7 | E8: ='Microsoft DCF Model'!I34 -> 2899966.7 | G8: ='Microsoft 3-Statement Model'!H26 -> 281724 | H8: =I8+'Microsoft 3-Statement Model'!H66 -> 196834 | I8: ='Microsoft 3-Statement Model'!H34+'Microsoft 3-Statement Model'!H66 -> 162681 | J8: ='Microsoft 3-Statement Model'!H37 -> 106733 | L8: =E8/G8 -> 10.293644 | M8: =E8/H8 -> 14.733058 | N8: =E8/I8 -> 17.826093 | O8: =D8/J8 -> 26.885974
B11: Valuation and Profitability Summary
B12: Higher EV/ Sales | C12: Higher EV/ EBITDA | D12: Higher P/E | E12: Better EBITDA Margin | F12: Better Net Margin
B13: Microsoft | C13: Apple | D13: Apple | E13: Microsoft | F13: Microsoft
B14: Summary:
B15: Microsoft trades at a higher EV/Sales multiple, suggesting the market places a higher value on each dollar of Microsoft revenue. Apple trades at higher EV/EBITDA, EV/EBIT, and P/E multiples, meaning Apple is more expensive based on EBITDA, operating income, and earnings. Microsoft shows stronger profitability, with better EBITDA and net margins, which suggests it converts revenue into profit more efficiently than Apple.
B17: DCF Comparison
B18: Metric | C18: Apple | D18: Microsoft
B19: Current Share Price | C19: ='Apple DCF Model'!D12 -> 231.27 | D19: ='Microsoft DCF Model'!D12 -> 384.41
B20: DCF Implied Share Price | C20: ='Apple DCF Model'!D36 -> 236.72634 | D20: ='Microsoft DCF Model'!D36 -> 414.03185
B21: Upside/Downside | C21: ='Apple DCF Model'!N36 -> 0.023592956 | D21: ='Microsoft DCF Model'!N36 -> 0.077057969
B22: Terminal Growth Rate | C22: 0.04 | D22: 0.025
B23: Discount Rate | C23: =0.075 -> 0.075 | D23: ='Microsoft DCF Model'!D7 -> 0.09
B24: Selected Terminal Value ($M) | C24: ='Apple DCF Model'!N21 -> 4436337 | D24: ='Microsoft DCF Model'!N21 -> 3995349.9
B25: Implied Equity Value ($M) | C25: ='Apple DCF Model'!D34 -> 3578355.4 | D25: ='Microsoft DCF Model'!D34 -> 3090747.8
B26: Implied Enterprise Value ($M) | C26: ='Apple DCF Model'!D31 -> 3598934.4 | D26: ='Microsoft DCF Model'!D31 -> 3121093.8
B48: Summary:
B49: This analysis compares Apple and Microsoft using trading multiples and DCF-implied valuation. Apple trades at higher EV/EBITDA, EV/EBIT, and P/E multiples, suggesting it is more expensive on profit-based valuation metrics. Microsoft has stronger profitability, with better EBITDA and net margins, and shows higher DCF upside under the base-case assumptions. Apple’s DCF valuation uses a lower discount rate and higher terminal growth rate, which makes its implied value more dependent on optimistic assumptions. Based on the current model outputs, Apple appears slightly undervalued, while Microsoft appears modestly undervalued with stronger relative upside.

Sheet Microsoft DCF Model
B1: In Millions Of $
B3: DCF Model
B5: Assumptions
B6: Tax Rate | D6: ='[1] 3-Statement Model'!$M$14 -> 0.16806955
B7: Discount Rate | D7: 0.09
B8: Perpetural Growth Rate | D8: 0.025
B9: EV/EBITDA Mulltiple | D9: 20.0x
B10: Transaction Date | D10: 45838
B11: Fiscal Year End | D11: 45838
B12: Current Price | D12: 384.41
B13: Shares Outstanding | D13: 7465
B14: Debt | D14: ='[1] 3-Statement Model'!H51 -> 60588
B15: Cash | D15: ='[1] 3-Statement Model'!H43 -> 30242
B16: Capex | D16: ='[1] 3-Statement Model'!M18 -> -40255.25
B18: Discounted Cash Flow | D18: Entry | E18: =2026 -> 2026 | F18: =E18+1 -> 2027 | G18: =F18+1 -> 2028 | H18: =G18+1 -> 2029 | I18: =H18+1 -> 2030 | J18: Exit
B19: Date | D19: 45838 | E19: =D19+365 -> 46203 | F19: =E19+365 -> 46568 | G19: =F19+366 -> 46934 | H19: =G19+365 -> 47299 | I19: =H19+365 -> 47664 | J19: =I19 -> 47664 | L19: Terminal Value
B20: EBIT | D20: - | E20: ='[1] 3-Statement Model'!I34 -> 140028.13 | F20: ='[1] 3-Statement Model'!J34 -> 157524.24 | G20: ='[1] 3-Statement Model'!K34 -> 177206.45 | H20: ='[1] 3-Statement Model'!L34 -> 199347.89 | I20: ='[1] 3-Statement Model'!M34 -> 224255.84 | J20: - | L20: Perpetual Growth | N20: =((I25)*(1+$D$8)/($D$7-$D$8)) -> 2751771.4
B21: Less: Cash Taxes | D21: - | E21: =E20*$D$6 -> 23534.464 | F21: =F20*$D$6 -> 26475.029 | G21: =G20*$D$6 -> 29783.008 | H21: =H20*$D$6 -> 33504.31 | I21: =I20*$D$6 -> 37690.579 | J21: - | L21: Average | N21: =AVERAGE(N20,N22) -> 3995349.9
B22: Plus: D&A | D22: - | E22: ='[1] 3-Statement Model'!I66 -> 33550.679 | F22: ='[1] 3-Statement Model'!J66 -> 34529.589 | G22: ='[1] 3-Statement Model'!K66 -> 35365.573 | H22: ='[1] 3-Statement Model'!L66 -> 36079.497 | I22: ='[1] 3-Statement Model'!M66 -> 36689.184 | J22: - | L22: EV/EBITDA | N22: =((I20+I21)*20) -> 5238928.5
B23: Less: Capex | D23: - | E23: =ABS('[1] 3-Statement Model'!I72) -> 40255.25 | F23: =ABS('[1] 3-Statement Model'!J72) -> 40255.25 | G23: =ABS('[1] 3-Statement Model'!K72) -> 40255.25 | H23: =ABS('[1] 3-Statement Model'!L72) -> 40255.25 | I23: =ABS('[1] 3-Statement Model'!M72) -> 40255.25 | J23: -
B24: Less: Changes in NWC | D24: - | E24: ='[1] 3-Statement Model'!I92 -> 4647.5138 | F24: ='[1] 3-Statement Model'!J92 -> 5968.2902 | G24: ='[1] 3-Statement Model'!K92 -> 6714.0111 | H24: ='[1] 3-Statement Model'!L92 -> 7552.9077 | I24: ='[1] 3-Statement Model'!M92 -> 8496.6221 | J24: -
B25: Unlevered FCF | D25: - | E25: =((E20)-(E21)+(E22)-(E23)-(E24)) -> 105141.58 | F25: =((F20)-(F21)+(F22)-(F23)-(F24)) -> 119355.26 | G25: =((G20)-(G21)+(G22)-(G23)-(G24)) -> 135819.75 | H25: =((H20)-(H21)+(H22)-(H23)-(H24)) -> 154114.92 | I25: =((I20)-(I21)+(I22)-(I23)-(I24)) -> 174502.58 | J25: -
B26: (Entry)/Exit | D26: =-I34 -> -2899966.7 | J26: =N21 -> 3995349.9
B27: Transaction CF | D27: =D26 -> -2899966.7 | E27: =E25 -> 105141.58 | F27: =F25 -> 119355.26 | G27: =G25 -> 135819.75 | H27: =H25 -> 154114.92 | I27: =I25 -> 174502.58 | J27: =I27+J26 -> 4169852.5
B30: Intrinsic Value | G30: Market Value | L30: Rate of Return
B31: Enterprise Value | D31: =E25/(1+$D$7)^1+F25/(1+$D$7)^2+G25/(1+$D$7)^3+H25/(1+$D$7)^4+I25/(1+$D$7)^5+J26/(1+$D$7)^5 -> 3121093.8 | G31: Market Cap | I31: =D13*D12 -> 2869620.7 | L31: Target Price Upside | N31: =(N37/N35-1) -> 0.077057969
B32: Plus: Cash | D32: =+D15 -> 30242 | G32: Plus: Debt | I32: =D14 -> 60588 | L32: Internal Rate of Return (IRR) | N32: =IRR(D27:J27) -> 0.097473146
B33: Less: Debt | D33: =+D14 -> 60588 | G33: Less: Cash | I33: =+D15 -> 30242
B34: Equity Value | D34: =D31+D32-D33 -> 3090747.8 | G34: Enterprise Value | I34: =I31+I32-I33 -> 2899966.7 | L34: Market Value vs Intrinsic Value
L35: Market Value | N35: =I36 -> 384.41
B36: Equity Value/Share | D36: =D34/D13 -> 414.03185 | G36: Equity Value/Share | I36: =D12 -> 384.41 | L36: Upside | N36: =N37/N35-1 -> 0.077057969
L37: Intrinsic Value | N37: =D36 -> 414.03185

Sheet Microsoft 3-Statement Model
D1: Historical Results | I1: Forecast Period
A2: In Millions of US $ | D2: 2021 | E2: =+D2+1 -> 2022 | F2: =+E2+1 -> 2023 | G2: =+F2+1 -> 2024 | H2: =+G2+1 -> 2025 | I2: =+H2+1 -> 2026 | J2: =+I2+1 -> 2027 | K2: =+J2+1 -> 2028 | L2: =+K2+1 -> 2029 | M2: =+L2+1 -> 2030
A5: Assumptions
A7: Key Assumptions
A8: Revenue Growth (% Change) | D8: - | E8: - | F8: =(F26/E26)-1 -> 0.068820296 | G8: =(G26/F26)-1 -> 0.15669962 | H8: =(H26/G26)-1 -> 0.14932156 | I8: =AVERAGE($F$8:$H$8) -> 0.12494716 | J8: =AVERAGE($F$8:$H$8) -> 0.12494716 | K8: =AVERAGE($F$8:$H$8) -> 0.12494716 | L8: =AVERAGE($F$8:$H$8) -> 0.12494716 | M8: =AVERAGE($F$8:$H$8) -> 0.12494716
A9: Cost of Goods Sold (% of Revenue) | D9: - | E9: =E27/E26 -> 0.31598326 | F9: =F27/F26 -> 0.31079914 | G9: =G27/G26 -> 0.30235556 | H9: =H27/H26 -> 0.31176258 | I9: =AVERAGE($E$9:$H$9) -> 0.31022513 | J9: =AVERAGE($E$9:$H$9) -> 0.31022513 | K9: =AVERAGE($E$9:$H$9) -> 0.31022513 | L9: =AVERAGE($E$9:$H$9) -> 0.31022513 | M9: =AVERAGE($E$9:$H$9) -> 0.31022513
A10: Salaries and Benefits (% of Revenue) | D10: - | E10: =E31/E26 -> 0.13983457 | F10: =F31/F26 -> 0.1431423 | G10: =G31/G26 -> 0.13081241 | H10: =H31/H26 -> 0.11669932 | I10: =AVERAGE($E$10:$H$10) -> 0.13262215 | J10: =AVERAGE($E$10:$H$10) -> 0.13262215 | K10: =AVERAGE($E$10:$H$10) -> 0.13262215 | L10: =AVERAGE($E$10:$H$10) -> 0.13262215 | M10: =AVERAGE($E$10:$H$10) -> 0.13262215
A11: Rent and Overhead ($000's) | D11: - | E11: 0 | F11: 0 | G11: 0 | H11: 0 | I11: =H11 -> 0 | J11: =I11 -> 0 | K11: =J11 -> 0 | L11: =K11 -> 0 | M11: =L11 -> 0
A12: Depreciation & Amortization (% of PP&E) | D12: - | E12: =E66/E46 -> 0.16517031 | F12: =F66/F46 -> 0.12602398 | G12: =G66/G46 -> 0.14420389 | H12: =H66/H46 -> 0.14862765 | I12: =AVERAGE($E$12:$H$12) -> 0.14600646 | J12: =AVERAGE($E$12:$H$12) -> 0.14600646 | K12: =AVERAGE($E$12:$H$12) -> 0.14600646 | L12: =AVERAGE($E$12:$H$12) -> 0.14600646 | M12: =AVERAGE($E$12:$H$12) -> 0.14600646
A13: Interest (% of Debt) | D13: - | E13: 0 | F13: 0 | G13: 0 | H13: 0 | I13: =H13 -> 0 | J13: =I13 -> 0 | K13: =J13 -> 0 | L13: =K13 -> 0 | M13: =L13 -> 0
A14: Tax Rate (% of Earnings Before Tax) | D14: - | E14: =E36/E34 -> 0.13165753 | F14: =F36/F34 -> 0.19147566 | G14: =G36/G34 -> 0.17957106 | H14: =H36/H34 -> 0.16957394 | I14: =AVERAGE($E$14:$H$14) -> 0.16806955 | J14: =AVERAGE($E$14:$H$14) -> 0.16806955 | K14: =AVERAGE($E$14:$H$14) -> 0.16806955 | L14: =AVERAGE($E$14:$H$14) -> 0.16806955 | M14: =AVERAGE($E$14:$H$14) -> 0.16806955
A15: Accounts Receivable (Days) | D15: - | E15: =((E44/E26)*365) -> 81.481137 | F15: =((F44/F26)*365) -> 83.859661 | G15: =((G44/G26)*365) -> 84.762934 | H15: =((H44/H26)*365) -> 90.568517 | I15: =AVERAGE($E$15:$H$15) -> 85.168062 | J15: =AVERAGE($E$15:$H$15) -> 85.168062 | K15: =AVERAGE($E$15:$H$15) -> 85.168062 | L15: =AVERAGE($E$15:$H$15) -> 85.168062 | M15: =AVERAGE($E$15:$H$15) -> 85.168062
A16: Inventory (Days) | D16: - | E16: =((E45/E27)*365) -> 21.800958 | F16: =((F45/F27)*365) -> 13.854516 | G16: =((G45/G27)*365) -> 6.1363575 | H16: =((H45/H27)*365) -> 3.8980542 | I16: =AVERAGE($E$16:$H$16) -> 11.422471 | J16: =AVERAGE($E$16:$H$16) -> 11.422471 | K16: =AVERAGE($E$16:$H$16) -> 11.422471 | L16: =AVERAGE($E$16:$H$16) -> 11.422471 | M16: =AVERAGE($E$16:$H$16) -> 11.422471
A17: Accounts Payable (Days) | D17: - | E17: =(E50/E27)*365 -> 110.69433 | F17: =(F50/F27)*365 -> 100.27899 | G17: =(G50/G27)*365 -> 108.3269 | H17: =(H50/H27)*365 -> 115.21285 | I17: =AVERAGE($E$17:$H$17) -> 108.62827 | J17: =AVERAGE($E$17:$H$17) -> 108.62827 | K17: =AVERAGE($E$17:$H$17) -> 108.62827 | L17: =AVERAGE($E$17:$H$17) -> 108.62827 | M17: =AVERAGE($E$17:$H$17) -> 108.62827
A18: Capital Expenditures ($000's) | D18: - | E18: =E71 -> -23886 | F18: =F71 -> -28107 | G18: =G71 -> -44477 | H18: =H71 -> -64551 | I18: =AVERAGE($E$18:$H$18) -> -40255.25 | J18: =AVERAGE($E$18:$H$18) -> -40255.25 | K18: =AVERAGE($E$18:$H$18) -> -40255.25 | L18: =AVERAGE($E$18:$H$18) -> -40255.25 | M18: =AVERAGE($E$18:$H$18) -> -40255.25
A19: Debt Issuance (Repayment) ($000's) | D19: - | E19: =E75 -> -9023 | F19: =F75 -> -2750 | G19: =G75 -> -4675 | H19: =H75 -> -3216 | I19: =AVERAGE($E$19:$H$19) -> -4916 | J19: =AVERAGE($E$19:$H$19) -> -4916 | K19: =AVERAGE($E$19:$H$19) -> -4916 | L19: =AVERAGE($E$19:$H$19) -> -4916 | M19: =AVERAGE($E$19:$H$19) -> -4916
A20: Equity Issued (Repaid) ($000's) | D20: - | E20: =E76 -> -30855 | F20: =F76 -> -20379 | G20: =G76 -> -15252 | H20: =H76 -> -16364 | I20: =AVERAGE($E$20:$H$20) -> -20712.5 | J20: =AVERAGE($E$20:$H$20) -> -20712.5 | K20: =AVERAGE($E$20:$H$20) -> -20712.5 | L20: =AVERAGE($E$20:$H$20) -> -20712.5 | M20: =AVERAGE($E$20:$H$20) -> -20712.5
A21: Days in Period | D21: - | E21: 365 | F21: 365 | G21: 365 | H21: 365 | I21: =AVERAGE(E21:H21) -> 365 | J21: =AVERAGE(F21:I21) -> 365 | K21: =AVERAGE(G21:J21) -> 365 | L21: =AVERAGE(H21:K21) -> 365 | M21: =AVERAGE(I21:L21) -> 365
A24: Income Statement
A26: Revenue | D26: - | E26: 198270 | F26: 211915 | G26: 245122 | H26: 281724 | I26: =((H26)*(1+I8)) -> 316924.61 | J26: =((I26)*(1+J8)) -> 356523.44 | K26: =((J26)*(1+K8)) -> 401070.04 | L26: =((K26)*(1+L8)) -> 451182.6 | M26: =((L26)*(1+M8)) -> 507556.58
A27: Cost of Goods Sold (COGS) | D27: - | E27: 62650 | F27: 65863 | G27: 74114 | H27: 87831 | I27: =((I26)*I9) -> 98317.981 | J27: =((J26)*J9) -> 110602.53 | K27: =((K26)*K9) -> 124422.01 | L27: =((L26)*L9) -> 139968.18 | M27: =((M26)*M9) -> 157456.81
A28: Gross Profit | D28: - | E28: 135620 | F28: 146052 | G28: 171008 | H28: 193893 | I28: =I26-I27 -> 218606.63 | J28: =J26-J27 -> 245920.91 | K28: =K26-K27 -> 276648.03 | L28: =L26-L27 -> 311214.42 | M28: =M26-M27 -> 350099.77
A29: Expenses | D29: -
A30: Research and Development Expenses | D30: - | E30: 24512 | F30: 27195 | G30: 29510 | H30: 32488 | I30: =((H30*(1+I8))) -> 36547.283 | J30: =((I30*(1+J8))) -> 41113.763 | K30: =((J30*(1+K8))) -> 46250.81 | L30: =((K30*(1+L8))) -> 52029.718 | M30: =((L30*(1+M8))) -> 58530.683
A31: SG&A Expenses | D31: - | E31: 27725 | F31: 30334 | G31: 32065 | H31: 32877 | I31: =((I26)*(I10)) -> 42031.224 | J31: =((J26)*(J10)) -> 47282.906 | K31: =((K26)*(K10)) -> 53190.77 | L31: =((L26)*(L10)) -> 59836.806 | M31: =((M26)*(M10)) -> 67313.245
A32: Other Operating Income or Expenses | D32: - | E32: - | F32: - | G32: - | H32: - | I32: - | J32: - | K32: - | L32: - | M32: -
A33: Total Expenses | D33: - | E33: =SUM(E30,E31,E32) -> 52237 | F33: =SUM(F30,F31,F32) -> 57529 | G33: =SUM(G30,G31,G32) -> 61575 | H33: =SUM(H30,H31,H32) -> 65365 | I33: =SUM(I30,I31,I32) -> 78578.507 | J33: =SUM(J30,J31,J32) -> 88396.668 | K33: =SUM(K30,K31,K32) -> 99441.581 | L33: =SUM(L30,L31,L32) -> 111866.52 | M33: =SUM(M30,M31,M32) -> 125843.93
A34: Earnings Before Tax | D34: - | E34: =(E28-E33) -> 83383 | F34: =(F28-F33) -> 88523 | G34: =(G28-G33) -> 109433 | H34: =(H28-H33) -> 128528 | I34: =(I28-I33) -> 140028.13 | J34: =(J28-J33) -> 157524.24 | K34: =(K28-K33) -> 177206.45 | L34: =(L28-L33) -> 199347.89 | M34: =(M28-M33) -> 224255.84
A36: Taxes | D36: - | E36: 10978 | F36: 16950 | G36: 19651 | H36: 21795 | I36: =((I34*I14)) -> 23534.464 | J36: =((J34*J14)) -> 26475.029 | K36: =((K34*K14)) -> 29783.008 | L36: =((L34*L14)) -> 33504.31 | M36: =((M34*M14)) -> 37690.579
A37: Net Earnings | D37: - | E37: =E34-E36 -> 72405 | F37: =F34-F36 -> 71573 | G37: =G34-G36 -> 89782 | H37: =H34-H36 -> 106733 | I37: =I34-I36 -> 116493.66 | J37: =J34-J36 -> 131049.21 | K37: =K34-K36 -> 147423.44 | L37: =L34-L36 -> 165843.58 | M37: =M34-M36 -> 186565.27
A40: Balance Sheet
A42: Assets
A43: Cash | D43: - | E43: 13931 | F43: 34704 | G43: 18315 | H43: 30242 | I43: =I81 -> 109755.08 | J43: =J81 -> 203481.84 | K43: =K81 -> 313673.09 | L43: =L81 -> 442159.51 | M43: =M81 -> 591033.59
A44: Accounts Receivable | D44: - | E44: 44261 | F44: 48688 | G44: 56924 | H44: 69905 | I44: =((I26/365)*I15) -> 73950.288 | J44: =((J26/365)*J15) -> 83190.167 | K44: =((K26/365)*K15) -> 93584.542 | L44: =((L26/365)*L15) -> 105277.66 | M44: =((M26/365)*M15) -> 118431.81
A45: Inventory | D45: - | E45: 3742 | F45: 2500 | G45: 1246 | H45: 938 | I45: =((I27/365)*I16) -> 3076.8064 | J45: =((J27/365)*J16) -> 3461.2446 | K45: =((K27/365)*K16) -> 3893.7173 | L45: =((L27/365)*L16) -> 4380.2262 | M45: =((M27/365)*M16) -> 4927.523
A46: Property & Equipment | D46: - | E46: 87546 | F46: 109987 | G46: 154552 | H46: 229789 | I46: =I98 -> 236493.57 | J46: =J98 -> 242219.23 | K46: =K98 -> 247108.91 | L46: =L98 -> 251284.66 | M46: =M98 -> 254850.73
A47: Total Assets | D47: - | E47: =SUM(E43,E44,E45,E46) -> 149480 | F47: =SUM(F43,F44,F45,F46) -> 195879 | G47: =SUM(G43,G44,G45,G46) -> 231037 | H47: =SUM(H43,H44,H45,H46) -> 330874 | I47: =SUM(I43:I46) -> 423275.74 | J47: =SUM(J43:J46) -> 532352.48 | K47: =SUM(K43:K46) -> 658260.26 | L47: =SUM(L43:L46) -> 803102.07 | M47: =SUM(M43:M46) -> 969243.65
A49: Liabilities
A50: Accounts Payable | D50: - | E50: 19000 | F50: 18095 | G50: 21996 | H50: 27724 | I50: =((I27/365*I17)) -> 29260.581 | J50: =((J27/365*J17)) -> 32916.607 | K50: =((K27/365*K17)) -> 37029.444 | L50: =((L27/365*L17)) -> 41656.168 | M50: =((M27/365*M17)) -> 46860.988
A51: Debt | D51: - | E51: 61270 | F51: 59965 | G51: 67127 | H51: 60588 | I51: =(H51+I19) -> 55672 | J51: =(I51+J19) -> 50756 | K51: =(J51+K19) -> 45840 | L51: =(K51+L19) -> 40924 | M51: =(L51+M19) -> 36008
...

Sheet Apple DCF Model
B1: In Millions Of $
B3: DCF Model
B5: Assumptions
B6: Tax Rate | D6: =0.166 -> 0.166
B7: Discount Rate | D7: 0.075
B8: Perpetual Growth Rate | D8: 0.04
B9: EV/EBITDA Multiple | D9: 24.0x
B10: Transaction Date | D10: 45565
B11: Fiscal Year End | D11: 45565
B12: Current Price | D12: 231.27
B13: Shares Outstanding | D13: 15116
B14: Debt | D14: ='[2] 3-Statement Model'!H51 -> 85750
B15: Cash | D15: ='[2] 3-Statement Model'!H43 -> 65171
B16: Capex | D16: ='[2] 3-Statement Model'!I18 -> 9901.6
B18: Discounted Cash Flow | D18: Entry | E18: =2025 -> 2025 | F18: =E18+1 -> 2026 | G18: =F18+1 -> 2027 | H18: =G18+1 -> 2028 | I18: =H18+1 -> 2029 | J18: Exit
B19: Date | D19: 45565 | E19: =D19+365 -> 45930 | F19: =E19+365 -> 46295 | G19: =F19+365 -> 46660 | H19: =G19+366 -> 47026 | I19: =H19+365 -> 47391 | J19: =H19+365 -> 47391 | L19: Terminal Value
B20: EBIT | D20: - | E20: ='[2] 3-Statement Model'!I34 -> 120668.13 | F20: ='[2] 3-Statement Model'!J34 -> 132817.81 | G20: ='[2] 3-Statement Model'!K34 -> 146190.81 | H20: ='[2] 3-Statement Model'!L34 -> 160910.29 | I20: ='[2] 3-Statement Model'!M34 -> 177111.83 | J20: - | L20: Perpetual Growth | N20: =((I25)*(1+$D$8)/($D$7-$D$8)) -> 4367148.8
B21: Less: Cash Taxes | D21: - | E21: ='[2] 3-Statement Model'!I36 -> 20003.409 | F21: ='[2] 3-Statement Model'!J36 -> 22017.488 | G21: ='[2] 3-Statement Model'!K36 -> 24234.357 | H21: ='[2] 3-Statement Model'!L36 -> 26674.436 | I21: ='[2] 3-Statement Model'!M36 -> 29360.199 | J21: - | L21: Average | N21: =AVERAGE(N20,N22) -> 4436337
B22: Plus: D&A | D22: - | E22: ='[2] 3-Statement Model'!I66 -> 12466.201 | F22: ='[2] 3-Statement Model'!J66 -> 11766.314 | G22: ='[2] 3-Statement Model'!K66 -> 11257.428 | H22: ='[2] 3-Statement Model'!L66 -> 10887.419 | I22: ='[2] 3-Statement Model'!M66 -> 10618.386 | J22: - | L22: EV/EBITDA Multiple | N22: =((I20+I22)*24) -> 4505525.1
B23: Less: Capex | D23: - | E23: =ABS('[2] 3-Statement Model'!I71) -> 9901.6 | F23: =ABS('[2] 3-Statement Model'!J71) -> 9901.6 | G23: =ABS('[2] 3-Statement Model'!K71) -> 9901.6 | H23: =ABS('[2] 3-Statement Model'!L71) -> 9901.6 | I23: =ABS('[2] 3-Statement Model'!M71) -> 9901.6 | J23: -
B24: Less: Changes in NWC | D24: - | E24: ='[2] 3-Statement Model'!I67 -> -16490.985 | F24: ='[2] 3-Statement Model'!J67 -> 1122.6589 | G24: ='[2] 3-Statement Model'!K67 -> 1235.6958 | H24: ='[2] 3-Statement Model'!L67 -> 1360.114 | I24: ='[2] 3-Statement Model'!M67 -> 1497.0595 | J24: -
B25: Unlevered FCF | D25: - | E25: =(E20-E21+E22-E23-E24) -> 119720.31 | F25: =(F20-F21+F22-F23-F24) -> 111542.38 | G25: =(G20-G21+G22-G23-G24) -> 122076.59 | H25: =(H20-H21+H22-H23-H24) -> 133861.56 | I25: =(I20-I21+I22-I23-I24) -> 146971.35 | J25: -
B26: (Entry)/Exit | D26: =-I34 -> -3516456.3 | J26: =N21 -> 4436337
B27: Transaction CF | D27: =D26 -> -3516456.3 | E27: =E25 -> 119720.31 | F27: =F25 -> 111542.38 | G27: =G25 -> 122076.59 | H27: =H25 -> 133861.56 | I27: =I25 -> 146971.35 | J27: =J26+I27 -> 4583308.3
B30: Intrinsic Value | G30: Market Value | L30: Rate of Return
B31: Enterprise Value | D31: =E25/(1+$D$7)^1+F25/(1+$D$7)^2+G25/(1+$D$7)^3+H25/(1+$D$7)^4+I25/(1+$D$7)^5+J26/(1+$D$7)^5 -> 3598934.4 | G31: Market Cap | I31: =D13*D12 -> 3495877.3 | L31: Target Price Upside | N31: =(N37/N35-1) -> 0.023592956
B32: Plus: Cash | D32: =+D15 -> 65171 | G32: Plus: Debt | I32: =D14 -> 85750 | L32: Internal Rate of Return (IRR) | N32: =IRR(D27:J27) -> 0.072907248
B33: Less: Debt | D33: =+D14 -> 85750 | G33: Less: Cash | I33: =+D15 -> 65171
B34: Equity Value | D34: =D31+D32-D33 -> 3578355.4 | G34: Enterprise Value | I34: =I31+I32-I33 -> 3516456.3 | L34: Market Value vs Intrinsic Value
L35: Market Value | N35: =I36 -> 231.27
B36: Equity Value/Share | D36: =D34/D13 -> 236.72634 | G36: Equity Value/Share | I36: =D12 -> 231.27 | L36: Upside | N36: =N37/N35-1 -> 0.023592956
L37: Intrinsic Value | N37: =D36 -> 236.72634

Sheet Apple 3-Statement Model
D1: Historical Results | I1: Forecast Period
A2: In Millions of US $ | D2: 2020 | E2: =+D2+1 -> 2021 | F2: =+E2+1 -> 2022 | G2: =+F2+1 -> 2023 | H2: =+G2+1 -> 2024 | I2: =+H2+1 -> 2025 | J2: =+I2+1 -> 2026 | K2: =+J2+1 -> 2027 | L2: =+K2+1 -> 2028 | M2: =+L2+1 -> 2029
A5: Assumptions
A7: Key Assumptions
A8: Revenue Growth (% Change) | D8: =-D8 -> 0 | E8: =(E26/D26-1) -> 0.33259385 | F8: =(F26/E26-1) -> 0.077937876 | G8: =(G26/F26-1) -> -0.028004605 | H8: =(H26/G26-1) -> 0.020219941 | I8: =AVERAGE($E8:$H8) -> 0.10068676 | J8: =AVERAGE($E8:$H8) -> 0.10068676 | K8: =AVERAGE($E8:$H8) -> 0.10068676 | L8: =AVERAGE($E8:$H8) -> 0.10068676 | M8: =AVERAGE($E8:$H8) -> 0.10068676
A9: Cost of Goods Sold (% of Revenue) | D9: =(D27/D26) -> 0.61766752 | E9: =(E27/E26) -> 0.5822064 | F9: =(F27/F26) -> 0.56690369 | G9: =(G27/G26) -> 0.5586887 | H9: =(H27/H26) -> 0.5379365 | I9: =AVERAGE($D9:$H9) -> 0.57268057 | J9: =AVERAGE($D9:$H9) -> 0.57268057 | K9: =AVERAGE($D9:$H9) -> 0.57268057 | L9: =AVERAGE($D9:$H9) -> 0.57268057 | M9: =AVERAGE($D9:$H9) -> 0.57268057
A10: Salaries and Benefits (% of Revenue) | D10: - | E10: - | F10: - | G10: - | H10: - | I10: - | J10: - | K10: - | L10: - | M10: -
A11: Rent and Overhead ($000's) | D11: - | E11: - | F11: - | G11: - | H11: - | I11: - | J11: - | K11: - | L11: - | M11: -
A12: Depreciation & Amortization (% of PP&E) | D12: =(D66/D46) -> 0.30071261 | E12: =(E66/E46) -> 0.28610548 | F12: =(F66/F46) -> 0.26364651 | G12: =(G66/G46) -> 0.26350223 | H12: =(H66/H46) -> 0.25054729 | I12: =AVERAGE($D12:$H12) -> 0.27290282 | J12: =AVERAGE($D12:$H12) -> 0.27290282 | K12: =AVERAGE($D12:$H12) -> 0.27290282 | L12: =AVERAGE($D12:$H12) -> 0.27290282 | M12: =AVERAGE($D12:$H12) -> 0.27290282
A13: Interest (% of Debt) | D13: =-B3 -> 0 | E13: - | F13: - | G13: - | H13: - | I13: - | J13: - | K13: - | L13: - | M13: -
A14: Tax Rate (% of Earnings Before Tax) | D14: =(D36/D34) -> 0.14602945 | E14: =(E36/E34) -> 0.13333762 | F14: =(F36/F34) -> 0.16159147 | G14: =(G36/G34) -> 0.14646416 | H14: =(H36/H34) -> 0.2414378 | I14: =(AVERAGE($D14:$H14)) -> 0.1657721 | J14: =(AVERAGE($D14:$H14)) -> 0.1657721 | K14: =(AVERAGE($D14:$H14)) -> 0.1657721 | L14: =(AVERAGE($D14:$H14)) -> 0.1657721 | M14: =(AVERAGE($D14:$H14)) -> 0.1657721
A15: Accounts Receivable (Days) | D15: =(D44/D26)*365 -> 49.787534 | E15: =(E44/E26)*365 -> 51.390969 | F15: =(F44/F26)*365 -> 56.400205 | G15: =(G44/G26)*365 -> 58.075649 | H15: =(H44/H26)*365 -> 61.83256 | I15: =AVERAGE($D15:$H15) -> 55.497383 | J15: =AVERAGE($D15:$H15) -> 55.497383 | K15: =AVERAGE($D15:$H15) -> 55.497383 | L15: =AVERAGE($D15:$H15) -> 55.497383 | M15: =AVERAGE($D15:$H15) -> 55.497383
A16: Inventory (Days) | D16: =(D45/D27)*365 -> 8.7418834 | E16: =(E45/E27)*365 -> 11.276593 | F16: =(F45/F27)*365 -> 8.0756981 | G16: =(G45/G27)*365 -> 10.791292 | H16: =(H45/H27)*365 -> 12.642571 | I16: =AVERAGE($D16:$H16) -> 10.305607 | J16: =AVERAGE($D16:$H16) -> 10.305607 | K16: =AVERAGE($D16:$H16) -> 10.305607 | L16: =AVERAGE($D16:$H16) -> 10.305607 | M16: =AVERAGE($D16:$H16) -> 10.305607
A17: Accounts Payable (Days) | D17: =(D50/D27)*365 -> 117.29752 | E17: =(E50/E27)*365 -> 91.386673 | F17: =(F50/F27)*365 -> 80.237759 | G17: =(G50/G27)*365 -> 84.966727 | H17: =(H50/H27)*365 -> 79.624249 | I17: =AVERAGE($D17:$H17) -> 90.702585 | J17: =AVERAGE($D17:$H17) -> 90.702585 | K17: =AVERAGE($D17:$H17) -> 90.702585 | L17: =AVERAGE($D17:$H17) -> 90.702585 | M17: =AVERAGE($D17:$H17) -> 90.702585
A18: Capital Expenditures ($000's) | D18: =ABS(D71) -> 7309 | E18: =ABS(E71) -> 11085 | F18: =ABS(F71) -> 10708 | G18: =ABS(G71) -> 10959 | H18: =ABS(H71) -> 9447 | I18: 9901.6 | J18: 9901.6 | K18: 9901.6 | L18: 9901.6 | M18: 9901.6
A19: Debt Issuance (Repayment) ($000's) | D19: =D75 -> 2499 | E19: =E75 -> 12665 | F19: =F75 -> -123 | G19: =G75 -> -9901 | H19: =H75 -> -5998 | I19: =AVERAGE($D19:$H19) -> -171.6 | J19: =AVERAGE($D19:$H19) -> -171.6 | K19: =AVERAGE($D19:$H19) -> -171.6 | L19: =AVERAGE($D19:$H19) -> -171.6 | M19: =AVERAGE($D19:$H19) -> -171.6
A20: Equity Issued (Repaid) ($000's) | D20: =D76 -> -72358 | E20: =E76 -> -85971 | F20: =F76 -> -89402 | G20: =G76 -> -77550 | H20: =H76 -> -94949 | I20: =AVERAGE($D20:$H20) -> -84046 | J20: =AVERAGE($D20:$H20) -> -84046 | K20: =AVERAGE($D20:$H20) -> -84046 | L20: =AVERAGE($D20:$H20) -> -84046 | M20: =AVERAGE($D20:$H20) -> -84046
A21: Days in Period | D21: 365 | E21: 365 | F21: 365 | G21: 365 | H21: 365 | I21: 365 | J21: 365 | K21: 365 | L21: 365 | M21: 365
A24: Income Statement
A26: Revenue | D26: 274515 | E26: 365817 | F26: 394328 | G26: 383285 | H26: 391035 | I26: =H26*(1+I8) -> 430407.05 | J26: =I26*(1+J8) -> 473743.34 | K26: =J26*(1+K8) -> 521443.03 | L26: =K26*(1+L8) -> 573945.44 | M26: =L26*(1+M8) -> 631734.15
A27: Cost of Goods Sold (COGS) | D27: 169559 | E27: 212981 | F27: 223546 | G27: 214137 | H27: 210352 | I27: =I26*I9 -> 246485.75 | J27: =J26*J9 -> 271303.61 | K27: =K26*K9 -> 298620.29 | L27: =L26*L9 -> 328687.4 | M27: =M26*M9 -> 361781.87
A28: Gross Profit | D28: 104956 | E28: 152836 | F28: 170782 | G28: 169148 | H28: 180683 | I28: =I26-I27 -> 183921.3 | J28: =J26-J27 -> 202439.74 | K28: =K26-K27 -> 222822.74 | L28: =L26-L27 -> 245258.04 | M28: =M26-M27 -> 269952.28
A29: Expenses
A30: Research and Development Expenses | D30: 18752 | E30: 21914 | F30: 26251 | G30: 29915 | H30: 31370 | I30: =I26*(H30/H26) -> 34528.544 | J30: =J26*(I30/I26) -> 38005.111 | K30: =K26*(J30/J26) -> 41831.723 | L30: =L26*(K30/K26) -> 46043.624 | M30: =M26*(L30/L26) -> 50679.607
A31: SG&A Expenses | D31: 19916 | E31: 21973 | F31: 25094 | G31: 24932 | H31: 26097 | I31: =I26*(H31/H26) -> 28724.622 | J31: =J26*(I31/I26) -> 31616.812 | K31: =K26*(J31/J26) -> 34800.206 | L31: =L26*(K31/K26) -> 38304.126 | M31: =M26*(L31/L26) -> 42160.845
A32: Other Operating Income or Expenses | D32: - | E32: - | F32: - | G32: - | H32: - | I32: - | J32: - | K32: - | L32: - | M32: -
A33: Total Expenses | D33: =SUM(D30:D32) -> 38668 | E33: =SUM(E30:E32) -> 43887 | F33: =(F30+F31) -> 51345 | G33: 54847 | H33: 57467 | I33: =SUM(I30:I32) -> 63253.166 | J33: =SUM(J30:J32) -> 69621.923 | K33: =SUM(K30:K32) -> 76631.929 | L33: =SUM(L30:L32) -> 84347.75 | M33: =SUM(M30:M32) -> 92840.452
A34: Earnings Before Tax | D34: 66288 | E34: 108949 | F34: 119437 | G34: 114301 | H34: 123216 | I34: =I28-I33 -> 120668.13 | J34: =J28-J33 -> 132817.81 | K34: =K28-K33 -> 146190.81 | L34: =L28-L33 -> 160910.29 | M34: =M28-M33 -> 177111.83
A36: Taxes | D36: 9680 | E36: 14527 | F36: 19300 | G36: 16741 | H36: 29749 | I36: =I34*I14 -> 20003.409 | J36: =J34*J14 -> 22017.488 | K36: =K34*K14 -> 24234.357 | L36: =L34*L14 -> 26674.436 | M36: =M34*M14 -> 29360.199
A37: Net Earnings | D37: 57411 | E37: 94680 | F37: 99803 | G37: 96995 | H37: 93736 | I37: =I34-I36 -> 100664.72 | J37: =J34-J36 -> 110800.33 | K37: =K34-K36 -> 121956.45 | L37: =L34-L36 -> 134235.85 | M37: =M34-M36 -> 147751.63
A40: Balance Sheet
A42: Assets
A43: Cash | D43: 90943 | E43: 62639 | F43: 48304 | G43: 61555 | H43: 65171 | I43: =(I57-(I44+I45+I46)) -> 28777.707 | J43: =(J57-(J44+J45+J46)) -> 56102.489 | K43: =(K57-(K44+K45+K46)) -> 93961.475 | L43: =(L57-(L44+L45+L46)) -> 143605.43 | M43: =(M57-(M44+M45+M46)) -> 206359.19
A44: Accounts Receivable | D44: 37445 | E44: 51506 | F44: 60932 | G44: 60985 | H44: 66243 | I44: =(I26/I21)*I15 -> 65442.37 | J44: =(J26/J21)*J15 -> 72031.55 | K44: =(K26/K21)*K15 -> 79284.174 | L44: =(L26/L21)*L15 -> 87267.041 | M44: =(M26/M21)*M15 -> 96053.677
A45: Inventory | D45: 4061 | E45: 6580 | F45: 4946 | G45: 6331 | H45: 7286 | I45: =(I27/I21)*I16 -> 6959.4121 | J45: =(J27/J21)*J16 -> 7660.1327 | K45: =(K27/K21)*K16 -> 8431.4067 | L45: =(L27/L21)*L16 -> 9280.3378 | M45: =(M27/M21)*M16 -> 10214.745
A46: Property & Equipment | D46: 36766 | E46: 39440 | F46: 42117 | G46: 43715 | H46: 45680 | I46: =H46+I18-(H46*I12) -> 43115.399 | J46: =I46+J18-(I46*J12) -> 41250.685 | K46: =J46+K18-(J46*K12) -> 39894.857 | L46: =K46+L18-(K46*L12) -> 38909.038 | M46: =L46+M18-(L46*M12) -> 38192.251
A47: Total Assets | D47: =SUM(D43:D46) -> 169215 | E47: =SUM(E43:E46) -> 160165 | F47: =SUM(F43:F46) -> 156299 | G47: =SUM(G43:G46) -> 172586 | H47: =SUM(H43:H46) -> 184380 | I47: =SUM(I43:I46) -> 144294.89 | J47: =SUM(J43:J46) -> 177044.86 | K47: =SUM(K43:K46) -> 221571.91 | ... M47: =SUM(M43:M46) -> 350819.86
A49: Liabilities
A50: Accounts Payable | D50: 54490 | E50: 53325 | F50: 49142 | G50: 49848 | H50: 45888 | I50: =(I27/I21)*I17 -> 61251.767 | J50: =(J27/J21)*J17 -> 67419.009 | K50: =(K27/K21)*K17 -> 74207.211 | L50: =(L27/L21)*L17 -> 81678.895 | M50: =(M27/M21)*M17 -> 89902.879
A51: Debt | D51: 91807 | E51: 109106 | F51: 98959 | G51: 95281 | H51: 85750 | I51: =(H51+I19) -> 85578.4 | J51: =(I51+J19) -> 85406.8 | K51: =(J51+K19) -> 85235.2 | L51: =(K51+L19) -> 85063.6 | M51: =(L51+M19) -> 84892
...

Sheet Sensitivity Analysis Table
A1: Apple DCF Sensitivity Analysis Table
B2: Perpetual Growth Rate
B3: ='Apple DCF Model'!D36 -> 236.72634 | C3: 0.02 | D3: =C3+0.005 -> 0.025 | E3: =D3+0.005 -> 0.03 | F3: =E3+0.005 -> 0.035 | G3: =F3+0.005 -> 0.04
B4: Discount Rate
B5: 0.07 | C5: 209.73326 | D5: 217.97499 | E5: 228.27715 | F5: 241.52278 | G5: 259.18362
B6: =0.07+0.01 -> 0.08 | C6: 189.51078 | D6: 194.92488 | E6: 201.42181 | F6: 209.3625 | G6: 219.28837
B7: =0.07+0.02 -> 0.09 | C7: 173.84485 | D7: 177.62944 | E7: 182.04479 | F7: 187.26293 | G7: 193.5247
B8: =0.07+0.03 -> 0.1 | C8: 161.11419 | D8: 163.88122 | E8: 167.04354 | F8: 170.69237 | G8: 174.94934
B9: =0.07+0.04 -> 0.11 | C9: 150.41158 | D9: 152.50464 | E9: 154.85934 | F9: 157.528 | G9: 160.57789
A13: Microsoft DCF Sensitivity Analysis Table
B15: Perpetual Growth Rate
B16: ='Microsoft DCF Model'!D36 -> 414.03185 | C16: 0.02 | D16: 0.025 | E16: 0.03 | F16: 0.035 | G16: 0.04
B17: Discount Rate
B18: 0.07 | C18: 490.52005 | D18: 510.33506 | E18: 535.10383 | F18: 566.94939 | G18: 609.41014
B19: =B18+0.01 -> 0.08 | C19: 442.25709 | D19: 455.27386 | E19: 470.89397 | F19: 489.98523 | G19: 513.8493
B20: =B19+0.01 -> 0.09 | C20: 404.93283 | D20: 414.03185 | E20: 424.64738 | F20: 437.193 | G20: 452.24774
B21: =B20+0.01 -> 0.1 | C21: 374.65021 | D21: 381.30279 | E21: 388.90574 | F21: 397.67837 | G21: 407.91311
B22: =B21+0.01 -> 0.11 | C22: 349.229 | D22: 354.26121 | E22: 359.92245 | F22: 366.33851 | G22: 373.67116

Sheet Valuation Range Chart
A1: Apple vs. Microsoft Valuation Range Analysis
B5: Apple
C6: Range Start | D6: Low | E6: High | F6: Range End
B7: 52-Week Trading Range | C7: 196.86 | D7: 196.86 | E7: 317.4 | F7: 317.4
B8: Comparable Companies | C8: 129.59 | D8: 129.59 | E8: 265.09 | F8: 265.09
B9: DCF - Sensitivity Range | C9: 150.41 | D9: 150.41 | E9: 259.18 | F9: 259.18
B10: DCF - Base Case Range | C10: 209.36 | D10: 209.36 | E10: 241.52 | F10: 241.52
B11: Analyst Target Range | C11: 215 | D11: 215 | E11: 400 | F11: 400
B15: Microsoft
C16: Range Start | D16: Low | E16: High | F16: Range End
B17: 52-Week Trading Range | C17: 344.79 | D17: 344.79 | E17: 555.45 | F17: 555.45
B18: Comparable Companies | C18: 335.31 | D18: 335.31 | E18: 684.48 | F18: 684.48
B19: DCF - Sensitivity Range | C19: 349.23 | D19: 349.23 | E19: 609.41 | F19: 609.41
B20: DCF - Base Case Range | C20: 404.93 | D20: 404.93 | E20: 452.25 | F20: 452.25
B21: Analyst Target Range | C21: 392 | D21: 392 | E21: 675 | F21: 675
